Workbook
Name \1: #REF!
Name \1: #REF!
Name \2: #REF!
Name \A: [1]RS!#REF!
Name \A: [1]RS!#REF!
Name \A: #REF!
Name \b: #REF!
Name \b: #REF!
Name \b: #REF!
Name \b: #REF!
Name \B: #REF!
Name \b: #REF!
Name \C: #REF!
Name \C: #REF!
Name \C: #REF!
Name \C: #REF!
Name \c: #REF!
Name \C: #REF!
Name \D: #REF!
Name \D: #REF!
Name \e: #REF!
Name \F: #REF!
Name \G: #REF!
Name \H: #REF!
Name \i: #REF!
Name \i: #REF!
Name \i: #REF!
Name \i: #REF!
Name \J: #REF!
Name \K: #REF!
Name \l: #REF!
Name \l: #REF!
Name \l: #REF!
Name \l: #REF!
Name \m: #N/A
Name \M: #REF!
Name \M: #REF!
Name \M: #REF!
Name \n: #REF!
Name \n: #REF!
Name \n: #REF!
Name \n: #REF!
Name \O: #REF!
Name \P: #REF!
Name \Q: #REF!
Name \R: #REF!
Name \s: #REF!
Name \s: #REF!
Name \S: '[2]F&F'!#REF!
Name \s: #REF!
Name \s: #REF!
Name \S: '[2]F&F'!#REF!
Name \s: #REF!
Name \t: #REF!
Name \t: #REF!
Name \t: #REF!
Name \t: #REF!
Name \t: #REF!
Name \u: #REF!
Name \U: #REF!

Sheet Updated Trial 13
A2: SWIFT MOVERS (PVT.) LTD.
A4: Detailed Trial Balance
D6: Trial Balance KHI | F6: Trial Balance LHR | H6: Adjustment | J6: Adjusted Trial
A7: Account Name | D7: Debit | E7: Credit | F7: Debit | G7: Credit | H7: Debit | I7: Credit | J7: Debit | K7: Credit
A10: ASSETS
A11: CURRENT ASSETS
B12: CASH
A13: 1020101 | C13: CASH BOOK | D13: 1608.147 | F13: 11128 | J13: =(D13+F13+H13)-(E13+G13+I13) -> 12736.147
B15: BANK
A16: 1020203 | C16: BANK ALHABIB DOLLAR A/C | D16: 2009 | J16: =(D16+F16+H16)-(E16+G16+I16) -> 2009
A17: 1020204 | C17: BANK ALHABIB RUPEES A/C | D17: 4906.47 | J17: =(D17+F17+H17)-(E17+G17+I17) -> 4906.47
A18: 1020207 | C18: BANK ALHABIB RUPEES A/C (SSF) | D18: 470808 | I18: 100 | J18: =(D18+F18+H18)-(E18+G18+I18) -> 470708
A19: 1020201 | C19: FAYSAL BANK DOLLAR A/C | D19: 60643.25 | J19: =(D19+F19+H19)-(E19+G19+I19) -> 60643.25
A20: 1020202 | C20: FAYSAL BANK RUPEES A/C | D20: 624910.15 | J20: =(D20+F20+H20)-(E20+G20+I20) -> 624910.15
A21: Lhr | C21: BANK ALHABIB 095-01 | F21: 25374.55 | J21: =(D21+F21+H21)-(E21+G21+I21) -> 25374.55
B23: PETTY CASH
A24: 1020301 | C24: PETTY CASH BOOK | D24: 1882 | J24: =(D24+F24+H24)-(E24+G24+I24) -> 1882
B26: Advance Tax
A27: 1020420 | C27: ADVANCE INCOME TAX TELEPHONE | D27: 9554 | J27: =(D27+F27+H27)-(E27+G27+I27) -> 9554
A28: 1020422 | C28: ADVANCE INCOME TAXELECTRIC CHARGES | D28: 20306 | F28: 8000 | H28: ='Adj entry 13'!B26 -> 150 | I28: ='Adj entry 13'!C33 -> 1001 | J28: =(D28+F28+H28)-(E28+G28+I28) -> 27455
A29: 1020426 | C29: ADVANCE INCOMETAX - CASH WITHDRAWL | D29: 6956.8 | J29: =(D29+F29+H29)-(E29+G29+I29) -> 6956.8
A30: 1020425 | C30: ADVANCE INCOMTAX - MOBILE | D30: 6960 | H30: ='Adj entry 13'!B19 -> 11058 | J30: =(D30+F30+H30)-(E30+G30+I30) -> 18018
A31: Lhr | C31: DEFERRED TAX ASSETS | F31: 900708 | H31: -176364 | J31: =(D31+F31+H31)-(E31+G31+I31) -> 724344
A32: Lhr | C32: INCOME TAX REFUNDABLE (Asset) | F32: =132136+246068 -> 378204 | J32: =(D32+F32+H32)-(E32+G32+I32) -> 378204
A33: Lhr | C33: PROVISION FOR CURRENT TAX | I33: ='Adj entry 13'!C5 -> #REF! | K33: =(E33+G33+I33)-(D33+F33+H33) -> #REF!
A34: Lhr | C34: DEFERRED TAX | F34: 505428 | J34: =(D34+F34+H34)-(E34+G34+I34) -> 505428
C35: DEFFERD TAX INCOME 2013 | I35: =-'Adj entry 13'!C11 -> #REF! | K35: =(E35+G35+I35)-(D35+F35+H35) -> #REF!
B37: ADVANCE DEPOSITS & PREPAYMENTS
A38: 1020417 | C38: MR ADNAN | D38: 37500 | J38: =(D38+F38+H38)-(E38+G38+I38) -> 37500
A39: 1020432 | C39: MR. ALI SHER | D39: 10000 | J39: =(D39+F39+H39)-(E39+G39+I39) -> 10000
A40: 1020430 | C40: MR. MAHFOOZ | D40: 6000 | J40: =(D40+F40+H40)-(E40+G40+I40) -> 6000
A41: 1020434 | C41: MR. RAMISH MUKADAM | D41: 5000 | J41: =(D41+F41+H41)-(E41+G41+I41) -> 5000
A42: 1020412 | C42: MR.ZOHAIB | D42: 11500 | J42: =(D42+F42+H42)-(E42+G42+I42) -> 11500
C44: Insurance Prepaid | H44: ='Adj entry 13'!B22 -> 22144 | J44: =(D44+F44+H44)-(E44+G44+I44) -> 22144
B46: Secutity Deposits
A47: 1020408 | C47: SECURITY DEPOSIT MOBILE | D47: 18500 | J47: =(D47+F47+H47)-(E47+G47+I47) -> 18500
A48: 1020409 | C48: SECURITY DEPOSIT OFFICE | D48: 42000 | J48: =(D48+F48+H48)-(E48+G48+I48) -> 42000
A49: 1020206 | C49: SECURITY DEPOSIT (NESTLE) | F49: 1000 | J49: =(D49+F49+H49)-(E49+G49+I49) -> 1000
A50: 1020202 | C50: SECURITY DEPOSIT-OFFICE | F50: 150000 | J50: =(D50+F50+H50)-(E50+G50+I50) -> 150000
A51: 1020203 | C51: SECURITY DEPOSIT-PUMP | F51: 5000 | J51: =(D51+F51+H51)-(E51+G51+I51) -> 5000
...

Sheet Adj entry 13
A1: Swift Movers (Pvt) Limited
A2: Adjusting entries for the year ended on 30 June, 2013
A3: Particulars | B3: Debit | C3: Credit | D3: Refferd Trial | E3: Client trial
A4: Provision for Current tax | B4: ='C.tax computation'!K34 -> #REF! | E4: Lahore
A5: Tax Refund Due form Govt | C5: =B4 -> #REF! | E5: Lahore
B6: =SUM(B4:B5) -> #REF! | C6: =SUM(C4:C5) -> #REF! | D6: POSTED
A7: Acc.Depreciation Computer Assecories | B7: 417 | E7: Lahore
A8: Depreciation (Administrative Expense) | C8: =B7 -> 417 | E8: Lahore
B9: =SUM(B7:B8) -> 417 | C9: =SUM(C7:C8) -> 417 | D9: POSTED
A10: Defferd Tax expense | B10: ='Def tax'!H64 -> #REF! | E10: Lahore
A11: Defferd tax asset | C11: =B10 -> #REF! | E11: Lahore
B12: =SUM(B10:B11) -> #REF! | C12: =SUM(C10:C11) -> #REF! | D12: POSTED
A13: Swift Movers ltd Karachi | B13: 9429494 | E13: Karachi
A14: Swift Movers Lahore | C14: =B13 -> 9429494 | E14: Karachi
B15: =SUM(B13:B14) -> 9429494 | C15: =SUM(C13:C14) -> 9429494 | D15: POSTED
A16: Eobi | B16: 0 | E16: Karachi
A17: Staff Salary | C17: =B16 -> 0 | E17: Karachi
B18: =SUM(B16:B17) -> 0 | C18: =SUM(C16:C17) -> 0 | D18: POSTED
A19: Advance Tax Mobile | B19: 11058 | E19: Karachi
A20: Mobile Charges | C20: =B19 -> 11058 | E20: Karachi
B21: =SUM(B19:B20) -> 11058 | C21: =SUM(C19:C20) -> 11058 | D21: POSTED
A22: Prepaid Insurance | B22: 22144 | E22: Karachi | F22: 22144
A23: Expenses Payable | B23: 69398 | E23: Lahore | F23: 69398
A24: Insurance Expense | C24: 91542 | E24: Karachi | G24: 91542
B25: =SUM(B22:B24) -> 91542 | C25: =SUM(C22:C24) -> 91542 | D25: POSTED
A26: Advance Tax On Electricity | B26: 150 | E26: Lahore
A27: Electricity Expense | C27: 150 | E27: Lahore
B28: =SUM(B26:B27) -> 150 | C28: =SUM(C26:C27) -> 150 | D28: POSTED
A29: Electricity Expense | B29: 5992 | E29: Lahore
A30: Expenses Payable | C30: 5992 | E30: Lahore
B31: =SUM(B29:B30) -> 5992 | C31: =SUM(C29:C30) -> 5992 | D31: POSTED
A32: Electricity expense | B32: 1001 | E32: Karachi
A33: Advance Tax Electricity | C33: 1001 | E33: Karachi
B34: =SUM(B32:B33) -> 1001 | C34: =SUM(C32:C33) -> 1001 | D34: POSTED
A35: Electricity expense | B35: 10576 | E35: Karachi
A36: Expense Payable | C36: 10576 | E36: Karachi
B37: =SUM(B35:B36) -> 10576 | C37: =SUM(C35:C36) -> 10576 | D37: POSTED
A38: Telephone Expense | B38: 8700 | E38: Karachi
A39: Expense Payable | C39: 8700 | E39: Karachi
B40: =SUM(B38:B39) -> 8700 | C40: =SUM(C38:C39) -> 8700 | D40: POSTED

Sheet Trial Combine 19
A1: =SOFP!A1 -> AIMAL KHAN TRADERS
A2: TRIAL BALANCE AS AT 30 JUNE, 2019
C6: KARACHI OFFICE | E6: LAHORE OFFICE | G6: ADJUSTING ENTRIES | I6: ADJUSTED TRIAL
C7: Debit | D7: Credit | E7: Debit | F7: Credit | G7: Debit | H7: Credit | I7: Debit | J7: Credit
A8: CASH
A9: 1020101 | B9: CASH BOOK | C9: 8925 | D9: 0 | E9: 0 | I9: =C9+G9 -> 8925 | J9: =D9+H9 -> 0
A10: 1020301 | B10: CASH BOOK | I10: =C10+G10 -> 0 | J10: =D10+H10 -> 0
A11: BANK | I11: =C11+G11 -> 0 | J11: =D11+H11 -> 0
A12: 1020203 | B12: BANK ALHABIB DOLLAR A/C | I12: =C12+G12 -> 0 | J12: =D12+H12 -> 0
A13: 1020204 | B13: BANK ALHABIB RUPEES A/C | C13: 0 | G13: 0 | I13: =C13+G13 -> 0 | J13: =D13+H13 -> 0
B14: cash at bank | C14: 515289.57 | I14: =C14+G14 -> 515289.57 | J14: =D14+H14 -> 0
A15: 1020207 | B15: BANK ALHABIB RUPEES A/C (SSF) | C15: 0 | H15: ='Adj entry 19'!D30 -> 0 | I15: =C15+G15 -> 0 | J15: =D15+H15 -> 0
A16: 1020201 | B16: FAYSAL BANK DOLLAR A/C | C16: 0 | G16: ='Adj entry 19'!C22 -> 0 | I16: =C16+G16 -> 0 | J16: =D16+H16 -> 0
A17: 1020202 | B17: FAYSAL BANK RUPEES A/C | C17: 0 | I17: =C17+G17 -> 0 | J17: =D17+H17 -> 0
A18: 1020101 | B18: BANK AL HABIB 095-01 | C18: 0 | E18: 0 | G18: 0 | H18: ='Adj entry 19'!D17 -> 0 | I18: =C18+G18 -> 0 | J18: =D18+H18 -> 0
I19: =C19+G19 -> 0 | J19: =D19+H19 -> 0
A20: ADVANCE TAX | C20: 0 | I20: =C20+G20 -> 0 | J20: =D20+H20 -> 0
B21: wht on bank profit and cash withdrawl | C21: 15041.15 | I21: =C21+G21 -> 15041.15 | J21: =D21+H21 -> 0
A22: 1020201 | B22: ADVANCE INCOME TAX | C22: 0 | E22: 0 | H22: 0 | I22: =C22+G22 -> 0 | J22: =D22+H22 -> 0 | L22: =41180+23406+100432+39432 -> 204450 | M22: =H22-L22 -> -204450
A23: 1020211 | B23: ADVANCE INCOME TAX ELECTRIC | C23: 0 | E23: 0 | H23: 0 | I23: =C23+G23 -> 0 | J23: =D23+H23 -> 0
A24: 1020213 | B24: ADVANCE INCOME TAX MOBILE | C24: 0 | E24: 0 | H24: 0 | I24: =C24+G24 -> 0 | J24: =D24+H24 -> 0 | K24: =356475-344646 -> 11829
A25: 1020212 | B25: ADVANCE INCOME TAX ON CASH WITHDRAWAL | C25: 0 | E25: 0 | H25: 0 | I25: =C25+G25 -> 0 | J25: =D25+H25 -> 0
A26: 1020209 | B26: ADVANCE INCOME TAX ON TELE PH | C26: 0 | E26: 0 | H26: 0 | I26: =C26+G26 -> 0 | J26: =D26+H26 -> 0
A27: 1020420 | B27: ADVANCE INCOME TAX TELEPHONE | C27: 0 | E27: 0 | I27: =C27+G27 -> 0 | J27: =D27+H27 -> 0
A28: 1020429 | B28: ADVANCE INCOME TAX VEHICLE | C28: 0 | E28: 0 | I28: =C28+G28 -> 0 | J28: =D28+H28 -> 0
A29: 1020422 | B29: ADVANCE INCOME TAXELECTRIC CHARGES | C29: 0 | I29: =C29+G29 -> 0 | J29: =D29+H29 -> 0
A30: 1020426 | B30: ADVANCE INCOMETAX - CASH WITHDRAWL | C30: 0 | I30: =C30+G30 -> 0 | J30: =D30+H30 -> 0 | L30: =655+32138 -> 32793
A31: 1020425 | B31: ADVANCE INCOMTAX - MOBILE | C31: 0 | I31: =C31+G31 -> 0 | J31: =D31+H31 -> 0 | L31: =2322+516+3874 -> 6712
B32: REFUNDABLE INCOME TAX | C32: 0 | E32: 0 | G32: 0 | H32: 0 | I32: =C32+G32 -> 0 | J32: =D32+H32 -> 0
A33: 1020214 | B33: DEFERRED TAX ASSETS | C33: 0 | E33: 0 | G33: 0 | I33: =C33+G33 -> 0 | J33: =D33+H33 -> 0
A34: 1020207 | B34: INCOME TAX U/S 137 | C34: 0 | H34: =+'Adj entry 19'!D45 -> 0 | I34: =C34+G34 -> 0 | J34: =D34+H34 -> 0
B35: CURRENT YEAR INCOME TAX PROVISION REFUNDABLE / (PAYABLE) | F35: 0 | G35: 0 | H35: ='Adj entry 19'!D7 -> #REF! | I35: =C35+G35 -> 0 | J35: =D35+H35 -> #REF! | L35: =J213+H35 -> #REF!
I36: =C36+G36 -> 0 | J36: =D36+H36 -> 0
A37: ADVANCE DEPOSITS & PREPAYMENTS | I37: =C37+G37 -> 0 | J37: =D37+H37 -> 0
A38: 1020417 | B38: MR ADNAN | C38: 0 | I38: =C38+G38 -> 0 | J38: =D38+H38 -> 0 | N38: =I35-SOFP!#REF! -> #REF!
A39: 1020430 | B39: MR. MAHFOOZ | C39: 0 | I39: =C39+G39 -> 0 | J39: =D39+H39 -> 0
A40: 1020412 | B40: MR.ZOHAIB | I40: =C40+G40 -> 0 | J40: =D40+H40 -> 0
A41: 1020439 | B41: MUJTABA PARACHA | I41: =C41+G41 -> 0 | J41: =D41+H41 -> 0
A42: 1020431 | B42: RAHEEL UMAIR | I42: =C42+G42 -> 0 | J42: =D42+H42 -> 0
B43: security deposits | C43: 1200000 | I43: =C43+G43 -> 1200000 | J43: =D43+H43 -> 0
...

Sheet Adj entry 19
A1: SWIFT MOVERS PVT LIMITED
A2: AUDIT FOR THE YEAR ENDED 30 JUNE, 2019
A3: ADJUSTING ENTRIES
A5: Sr.No | B5: Particulars | C5: Debit | D5: Credit | E5: City | F5: Status
A6: 1 | B6: Income tax Expense | C6: ='C.tax computation'!K34 -> #REF! | F6: Posted
B7: Income tax provision | D7: =C6 -> #REF!
A9: =A6+1 -> 2 | B9: Deffered tax expense | C9: ='Def tax'!H64 -> #REF! | F9: Posted
B10: deferred tax liability | D10: =SUM(C9:C9) -> #REF!
A12: =A9+1 -> 3 | B12: Audit fee | C12: 50000 | F12: Posted
B13: Audit fee payable | D13: =SUM(C12:C12) -> 50000
B14: Reason :
C15: 0 | F15: Posted
A16: 4 | B16: Advertisement Expense | C16: 0
B17: Bank | D17: =C16 -> 0
A19: 5 | B19: AUDIT FEES | C19: 0 | F19: Posted
B20: EXPENSES PAYABLE | D20: =C19 -> 0
H21: =37695-#REF! -> #REF!
A22: 6 | B22: cash in foreign currency | C22: 0 | F22: Posted
B23: exchange gain | D23: =C22 -> 0
A25: 7 | C25: 0 | E25: 0 | F25: Posted
B26: Rent expense | C26: 0 | D26: =C25 -> 0 | H26: =356475-#REF! -> #REF!
B27: ='Trial Combine 19'!B45 -> SECURITY DEPOSIT OFFICE - lhr | D27: 0
A28: 8 | B28: Payable to staff provident fund account | C28: 0 | F28: Posted
B29: Bank charges | D29: 0
B30: Bank Al habib limited -57-01-8 | D30: 0
A31: 9 | B31: Provision for taxation | C31: 0 | F31: Posted
B32: Refundable income tax | C32: 0
B33: ADVANCE INCOME TAX | D33: 0
B34: ADVANCE INCOME TAX ELECTRIC | D34: 0
B35: ADVANCE INCOME TAX-VEHICLE | D35: 0
B36: ADVANCE INCOME TAX ON CASH WITHDRAWAL | D36: 0
B37: ADVANCE INCOME TAX ON TELE PH | D37: 0
B38: ADVANCE INCOME TAX ON MOBILE | D38: 0
G39: 97353
C40: =SUM(C6:C39) -> #REF! | D40: =SUM(D6:D39) -> #REF!
D42: =C40-D40 -> #REF!
B43: Other expenses | C43: 0
B44: Entertainment | C44: 0
B45: Prior year tax | D45: =+C43+C44 -> 0

Sheet grouping
A1: SWIFT MOVERS PRIVATE LIMITED
A2: FOR THE PERIOD ENDED JUNE 30, 2019
A4: Property and equipment
A5: A/C Code | B5: Accounting Description | C5: R.F | D5: 2019 | E5: 2015 | F5: 2018
B7: COST
B8: FURNITURE AND FIXTURES | D8: ='FIXED ASSETS'!L11 -> 700000 | F8: 321951
B9: OFFICE EQUIPMENT | D9: ='FIXED ASSETS'!L12 -> 112428 | F9: 720786
B10: COMPUTERS | D10: ='FIXED ASSETS'!L15 -> 732000 | F10: 472830
B11: GENERATOR | D11: ='FIXED ASSETS'!L16 -> 1068000 | F11: 155250
B12: MOTOR VEHICLE | D12: ='FIXED ASSETS'!L17 -> 8780816 | F12: 3392675
B13: MOTOR CYCLE | D13: ='FIXED ASSETS'!#REF! -> #REF! | F13: 73000
D14: =SUM(D8:D13) -> #REF! | E14: =SUM(E8:E12) -> 0 | F14: 5136492
B16: ACC. DEPRECIATION
B17: FURNITURE AND FIXTURES | D17: ='FIXED ASSETS'!X11 -> 35000 | F17: ='FIXED ASSETS'!X32 -> 265642
B18: OFFICE EQUIPMENT | D18: ='FIXED ASSETS'!X12 -> 4479 | F18: ='FIXED ASSETS'!X33 -> 525266
B19: COMPUTERS | D19: ='FIXED ASSETS'!X15 -> 27363 | F19: ='FIXED ASSETS'!X34 -> 451325
B20: GENERATOR | D20: ='FIXED ASSETS'!X16 -> 37550 | F20: ='FIXED ASSETS'!X35 -> 106532
B21: MOTOR VEHICLE | D21: ='FIXED ASSETS'!X17 -> 532276 | F21: ='FIXED ASSETS'!X36 -> 2417489
B22: MOTOR CYCLE | D22: ='FIXED ASSETS'!#REF! -> #REF! | F22: ='FIXED ASSETS'!X37 -> 70687
D23: =SUM(D17:D22) -> #REF! | F23: =SUM(F17:F22) -> 3836941
B25: NBV
B26: FURNITURE AND FIXTURES | D26: =D8-D17 -> 665000 | F26: =F8-F17 -> 56309
B27: OFFICE EQUIPMENT | D27: =D9-D18 -> 107949 | F27: =F9-F18 -> 195520
B28: COMPUTERS | D28: =D10-D19 -> 704637 | F28: =F10-F19 -> 21505
B29: GENERATOR | D29: =D11-D20 -> 1030450 | F29: =F11-F20 -> 48718
B30: MOTOR VEHICLE | D30: =D12-D21 -> 8248540 | F30: =F12-F21 -> 975186
B31: MOTOR CYCLE | D31: =D13-D22 -> #REF! | F31: =F13-F22 -> 2313
D32: =SUM(D26:D31) -> #REF! | F32: =SUM(F26:F31) -> 1299551
A38: Total | D38: =D32 -> #REF! | E38: =E32 -> 0 | F38: =F32 -> 1299551
A40: Long term deposits
A41: A/C Code | B41: Accounting Description | C41: R.F | D41: 2019 | E41: 2015 | F41: 2018
A43: 1020408 | B43: SECURITY DEPOSIT MOBILE | D43: ='Trial Combine 19'!I44 -> 0 | F43: 18500
A44: 1020409 | B44: SECURITY DEPOSIT OFFICE | D44: ='Trial Combine 19'!I45 -> 0 | F44: 192000
A45: 1020203 | B45: SECURITY DEPOSIT-PUMP | D45: ='Trial Combine 19'!I46 -> 0 | F45: 5000
A46: 1020206 | B46: SECURITY DEPOSIT (NESTLE) | D46: ='Trial Combine 19'!I47 -> 0 | F46: 1000
A58: Total | D58: =SUM(D42:D56) -> 0 | E58: =SUM(E42:E56) -> 0 | F58: =SUM(F42:F56) -> 216500
A60: CURRENT ASSETS
A61: A/C Code | B61: Accounting Description | C61: R.F | D61: =D41 -> 2019 | E61: 2015 | F61: =F41 -> 2018
B62: Trade debts - unsecured, considered good | D62: =D191 -> 0 | F62: =SOFP!#REF! -> #REF! | G62: =F62/E62 -> #REF!
B63: Due from related party | D63: =D212 -> 0 | F63: =SOFP!#REF! -> #REF!
...

Sheet Win
E13: AIMAL KHAN TRADERS
A15: Audited Financial Statements
A16: FOR THE YEAR ENDED DECEMBER 31, 2025

Sheet SOFP
A1: =Win!E13 -> AIMAL KHAN TRADERS
A2: STATEMENT OF FINANCIAL POSITION
A3: AS AT DECEMBER 31, 2025
D5: 2025 | F5: 2024 | H5: 2023
C6: Note | D6: Rupees | F6: Rupees | H6: Rupees
A8: ASSETS
A10: NON CURRENT ASSETS
B12: FIXED ASSETS - NET | C12: 5 | D12: ='Note 5 ''2025'!J11 -> 6008090.4 | F12: ='Note 5'!J11 -> 6675656.4 | H12: ='Note 5'!J13 -> 7417396
B13: Deferred taxation | D13: 0 | F13: 0 | H13: 0
A15: CURRENT ASSETS
B17: Stores and spares | C17: =NOTES!A200 -> 6 | D17: =NOTES!L203 -> 85471121 | F17: =NOTES!N203 -> 57016539 | H17: =NOTES!P203 -> 48319101 | J17: 40948391 | L17: 57016539
B18: Trade receivables | C18: =NOTES!#REF!+1 -> #REF! | D18: =NOTES!#REF! -> #REF! | F18: =NOTES!#REF! -> #REF! | H18: =NOTES!#REF! -> #REF! | M18: =F18-H18 -> #REF! | N18: =M18/H18 -> #REF!
B19: Due from related parties | C19: =+NOTES!#REF!+1 -> #REF! | D19: =NOTES!#REF! -> #REF! | F19: =NOTES!#REF! -> #REF! | H19: =NOTES!#REF! -> #REF! | M19: =F19-H19 -> #REF! | N19: =M19/H19 -> #REF!
B20: Advances and prepayments | C20: =+NOTES!#REF!+1 -> #REF! | D20: =NOTES!#REF! -> #REF! | F20: =NOTES!#REF! -> #REF! | H20: =NOTES!#REF! -> #REF! | M20: =F20-H20 -> #REF! | N20: =M20/H20 -> #REF!
B21: Trade receivables | D21: 77671960 | F21: =83235575 -> 83235575 | H21: 66310392 | J21: 54801977 | L21: 80235575 | M21: =F21-H21 -> 16925183 | N21: =M21/H21 -> 0.25524179
B22: Advances, deposits & other receivables | C22: =NOTES!A207 -> 7 | D22: =NOTES!L213 -> 24183427 | F22: =NOTES!N213 -> 20467854 | H22: =NOTES!P213 -> 17323147 | J22: 14672931 | L22: 20467854
B23: Cash and bank balances | C23: =NOTES!A215 -> 8 | D23: =NOTES!L219 -> 85418833 | F23: =NOTES!N219 -> 61683695 | H23: =NOTES!P217 -> 13746153 | J23: 11608328 | L23: 17633772
D24: =D23+D22+D21+D17 -> 2.7274534e+08 | F24: =F21+F22+F23+F17 -> 222403663 | H24: =H21+H22+H23+H17+1 -> 145698794 | J24: =SUM(J17:J23) -> 122031627 | L24: =SUM(L17:L23) -> 175353740
A26: TOTAL ASSETS | D26: =D24+D12+1 -> 2.7875343e+08 | F26: =F24+F12+1 -> 2.2907932e+08 | H26: =H24+H12 -> 153116190
A29: CAPITAL AND LIABILITIES
B31: Authorized capital | D31: =G31 -> 0 | F31: =I31 -> 0 | H31: =J31 -> 0
B32: CAPITAL ACCOUNT
B34: Capital Account | C34: 9 | D34: =NOTES!L232 -> 1.9490692e+08 | F34: =NOTES!N232 -> 1.5258328e+08 | H34: =NOTES!P232 -> 129332833
D35: =SUM(D34) -> 1.9490692e+08 | F35: =SUM(F34) -> 1.5258328e+08 | H35: =SUM(H34) -> 129332833
A37: NON CURRENT LIABILITIES
B39: Long Term Loan - Bank Alfalah | C39: 10.1 | D39: =NOTES!L250 -> 4935850.2 | F39: =NOTES!N250 -> 9280373 | H39: 0
B40: Long Term Loan - Habib Bank Limited | C40: 10.2 | D40: =NOTES!L270 -> 30000000 | F40: =NOTES!N270 -> 30000000 | H40: 0
D41: =SUM(D39:D40) -> 34935850 | F41: =SUM(F39:F40) -> 39280373 | H41: =SUM(H39:H40) -> 0
B43: Deposit for purchase of shares | D43: ='Trial Combine 19'!$J$286 -> 0 | F43: ='Trial Combine 19'!$J$286 -> 0 | H43: ='Trial Combine 19'!$J$286 -> 0
B44: Deferred taxation | D44: ='Trial Combine 19'!$J$33 -> 0 | F44: ='Trial Combine 19'!$J$33 -> 0 | H44: ='Trial Combine 19'!$J$33 -> 0
B46: Deferred tax liabilities | D46: 0 | F46: 0 | H46: 0
D47: =D43+D46 -> 0 | F47: =F43+F46 -> 0 | H47: =H43+H46 -> 0
A48: CURRENT LIABILITIES
B50: Current Liability - Long term loan | C50: 10.1 | D50: =NOTES!L249 -> 4344522.8 | F50: =NOTES!N249 -> 4659066.7 | H50: 0
B51: Creditors, accrued expenses & other liabilities | C51: 11 | D51: =NOTES!L279 -> 44566142 | F51: =NOTES!N279 -> 32556604 | H51: =NOTES!P279 -> 23783357 | J51: 21713168
B52: Due to related party | C52: =+NOTES!#REF! -> #REF! | D52: 0 | F52: 0 | H52: 0
B54: Current portion of liabilities
B55: against asset subject to finance lease | C55: =+NOTES!#REF! -> #REF! | D55: =NOTES!#REF! -> #REF! | F55: =NOTES!#REF! -> #REF! | H55: =NOTES!#REF! -> #REF!
D56: =SUM(D50:D51) -> 48910665 | F56: =SUM(F50:F51) -> 37215671 | H56: =SUM(H50:H51) -> 23783357 | J56: =SUM(J51:J55) -> 21713168 | L56: =+H56-J56 -> 2070189
A58: CONTINGENCIES AND COMMITMENTS | C58: 16 | D58: 0 | F58: 0 | H58: 0
...

Sheet CASH FLOW
A1: ='P & L'!A1 -> AIMAL KHAN TRADERS
A2: STATEMENT OF CASH FLOWS
A3: ='P & L'!A3 -> FOR THE YEAR ENDED DECEMBER 31, 2025
H5: ='P & L'!N5 -> 2023 | J5: ='P & L'!P5 -> 0
H6: Rupees | J6: Rupees
A8: CASH FLOW FROM OPERATING ACTIVITIES
A10: Profit/(loss) before taxation | H10: ='P & L'!N19 -> 76762135 | J10: ='P & L'!P19 -> 0
A11: Adjustment for non-cash and other items:
B12: Depreciation | H12: =-'FA-04'!L187 -> 1229125.1 | J12: 0
B13: Financial Charges | H13: =-'P & L'!#REF! -> #REF! | J13: =-'P & L'!#REF! -> #REF!
A14: Operating loss before working capital changes | H14: =H10+H12+H13 -> #REF! | J14: =J10+J12+J13 -> #REF!
A16: Net changes in working capital components:
A17: (Increase) / decrease in current assets
B18: =SOFP!B17 -> Stores and spares | H18: =SOFP!J17-SOFP!H17 -> -7370710 | J18: 0
B19: =SOFP!B22 -> Advances, deposits & other receivables | H19: =SOFP!J22-SOFP!H22 -> -2650216 | J19: 0
B20: Due from related parties | H20: 0 | J20: 0
B21: =SOFP!B21 -> Trade receivables | H21: =SOFP!J21-SOFP!H21 -> -11508415
A22: (Decrease) / increase in current liabilities
B23: =SOFP!B51 -> Creditors, accrued expenses & other liabilities | H23: =SOFP!H51-SOFP!J51 -> 2070189 | J23: 10000
C24: Due to related party | H24: =-SOFP!J52+SOFP!H52 -> 0 | J24: =-SOFP!#REF!+SOFP!J52 -> #REF!
H25: =ROUND(SUM(H18:H24),0) -> -19459152 | J25: =ROUND(SUM(J18:J24),0) -> #REF!
A26: Cash inflows from operating activities | H26: =H14+H25 -> #REF! | J26: =J14+J25 -> #REF!
B27: Income tax paid | H27: =-SOFP!J53 -> 0 | J27: 0
B28: Finance cost paid
B30: Financial charges paid | H30: ='P & L'!#REF! -> #REF! | J30: ='P & L'!#REF! -> #REF!
A31: Net cash generated from operating activities | H31: =H26+H27+H30 -> #REF! | J31: =J26+J27+J30 -> #REF!
A33: CASH FLOW FROM INVESTING ACTIVITIES
B34: Payments for Property, plant and equipment | H34: =-'FA-04'!L175 -> -9147966 | J34: 0
A36: Net cash (used in) from Investing activities | H36: =H34 -> -9147966 | J36: =J34 -> 0
A38: CASH FLOW FROM FINANCING ACTIVITIES
B39: Increase in paid up capital | H39: 0 | J39: 3000000
B40: =SOFP!#REF! -> #REF! | H40: =SOFP!#REF!-SOFP!#REF! -> #REF! | J40: 0
A41: NET INCREASE IN CASH AND CASH EQUIVALENTS | H41: =H31+H36+H39+H40 -> #REF! | J41: =J31+J36+J39+J40 -> #REF!
A43: CASH AND CASH EQUIVALENTS AT BEGINNING OF THE YEAR | H43: =J45 -> #REF! | J43: 0
A45: CASH AND CASH EQUIVALENTS AT END OF THE YEAR | G45: =NOTES!A215 -> 8 | H45: =H43+H369+H41 -> #REF! | J45: =J43+J369+J41 -> #REF!
A47: =+'P & L'!A33 -> The annexed notes form an integral part of these financial statements.
B53: =#REF! -> #REF! | J53: =#REF! -> #REF!
B54: =#REF! -> #REF! | J54: =#REF! -> #REF!
A55: SOFP | H55: =SOFP!H23 -> 13746153 | J55: =SOFP!J23 -> 11608328
A56: Difference | H56: =H45-H55 -> #REF! | J56: =J45-J55 -> #REF!

Sheet P & L
A1: =SOFP!A1 -> AIMAL KHAN TRADERS
A2: STATEMENT OF PROFIT OR LOSS
A3: =Win!A16 -> FOR THE YEAR ENDED DECEMBER 31, 2025
J5: 2025 | L5: 2024 | N5: =SOFP!H5 -> 2023
H6: Note | J6: Rupees | L6: Rupees | N6: Rupees
A8: Revenue- net | H8: 12 | J8: =NOTES!L282 -> 8.2445869e+08 | L8: =NOTES!N282 -> 732164323 | N8: =NOTES!P282 -> 650201889
A9: Cost of revenue | H9: 13 | J9: =-NOTES!L302 -> -6.7175285e+08 | L9: =-NOTES!N302 -> -6.1336297e+08 | N9: =-NOTES!P302 -> -545118808
A10: Gross Profit | J10: =SUM(J8:J9) -> 1.5270584e+08 | L10: =SUM(L8:L9) -> 1.1880135e+08 | N10: =SUM(N8:N9) -> 105083081
A12: OPERATING EXPENSES
A13: Administrative expenses | H13: 14 | J13: =NOTES!L318 -> 32608624 | L13: =NOTES!N318 -> 30396589 | N13: =NOTES!P318 -> 28312246
A14: Financial Charges | H14: 15 | J14: =NOTES!L337 -> 1327944.7 | L14: =NOTES!N337 -> 1061840.3 | N14: =NOTES!P337 -> 8700
J15: =SUM(J13:J14) -> 33936568 | L15: =SUM(L13:L14) -> 31458429 | N15: =SUM(N13:N14) -> 28320946
A16: OPERATING PROFIT FOR THE YEAR | J16: =+J10-J15 -> 1.1876927e+08 | L16: =+L10-L15 -> 87342920 | N16: =+N10-N15 -> 76762135
A18: Other Income | J18: 0 | L18: 0 | N18: 0
A19: Profit/(Loss) before taxation | J19: =+J16+J18 -> 1.1876927e+08 | L19: =+L16+L18 -> 87342920 | N19: =+N16+N18 -> 76762135
A21: Taxation | J21: =J19*0.13 -> 15440005 | L21: 10982465 | N21: 9753028
J22: 0 | L22: 0 | N22: 0
J23: ='Adj entry 19'!#REF! -> #REF! | L23: ='Adj entry 19'!#REF! -> #REF! | N23: ='Adj entry 19'!#REF! -> #REF!
J24: 0 | L24: 0 | N24: 0
J25: =SUM(J22:J24) -> #REF! | L25: =SUM(L22:L24) -> #REF! | N25: =SUM(N22:N24) -> #REF!
A27: Profit/(Loss) after taxation | J27: =J19-J21 -> 1.0332927e+08 | L27: =L19-L21 -> 76360455 | N27: =N19-N21 -> 67009107
A30: EARNINGS PER SHARE OF RS. 100 EACH -
B31: basic and diluted | H31: =+NOTES!#REF! -> #REF! | L31: =NOTES!#REF! -> #REF! | N31: =NOTES!#REF! -> #REF!
A33: =+SOFP!A62 -> The annexed notes form an integral part of these financial statements.
L51: =SOFP!F72 -> PROPRIETOR
B54: =SOFP!B71 -> 0
B55: =SOFP!B72 -> 0
Q78: 91381500
O79: 91381,500 3,600,000 500,000 800,000 709,300
O89: 800000
Q233: =SUM(Q232:Q232) -> 0
C249: There was no contingent liability of the business at the terminal date - Nil (2023: Nil).
C251: There was no capital commitment of the business at the terminal date- Nil (2023: Nil).

Sheet Cash Flows
A1: =SOFP!A1 -> AIMAL KHAN TRADERS
A2: STATEMENT OF CASH FLOW
A3: ='P & L'!A3 -> FOR THE YEAR ENDED DECEMBER 31, 2025
K5: 2025 | M5: 2024 | O5: 2023
K6: Rupees | M6: Rupees | O6: Rupees
A7: CASH FLOWS FROM OPERATING ACTIVITIES
B8: Profit/(Loss) before taxation | K8: ='P & L'!J27 -> 1.0332927e+08 | M8: ='P & L'!L27 -> 76360455 | O8: ='P & L'!N27 -> 67009107
A9: Adjustment for:
B11: Depreciation | K11: ='Note 5 ''2025'!H11 -> 667565.6 | M11: ='Note 5'!H11 -> 741739.6 | O11: ='Note 5'!H13 -> 824155
K12: =SUM(K11) -> 667565.6 | M12: =SUM(M11) -> 741739.6 | O12: =SUM(O11:O11) -> 824155
A13: Cash flow before working capital changes | K13: =+K8+K12 -> 1.0399683e+08 | M13: =+M8+M12 -> 77102195 | O13: =+O8+O12 -> 67833262
A14: Adjustment for working capital changes
B15: (Increase) / decrease in current assets
C16: Stores and spares | K16: =SOFP!F17-SOFP!D17 -> -28454582 | M16: =SOFP!H17-SOFP!F17 -> -8697438 | O16: =SOFP!J17-SOFP!H17 -> -7370710
C17: Trade receivables | K17: =SOFP!F21-SOFP!D21 -> 5563615 | M17: =SOFP!H21-SOFP!F21 -> -16925183 | O17: =SOFP!J21-SOFP!H21 -> -11508415
C18: Advances, deposits & other receivables | K18: =SOFP!F22-SOFP!D22 -> -3715572.5 | M18: =SOFP!H22-SOFP!F22 -> -3144707 | O18: =SOFP!J22-SOFP!H22 -> -2650216
K19: =SUM(K16:K18) -> -26606539 | M19: =SUM(M16:M18) -> -28767328 | O19: =SUM(O16:O18) -> -21529341
B20: Increase / (decrease) in current liabilities
C21: Current Liability | K21: =SOFP!D50-SOFP!F50 -> -314543.93 | M21: =SOFP!F50-SOFP!H50 -> 4659066.7 | O21: 0
C22: =SOFP!B51 -> Creditors, accrued expenses & other liabilities | K22: =-SOFP!F51+SOFP!D51 -> 12009538 | M22: =-SOFP!H51+SOFP!F51 -> 8773247 | O22: =SOFP!H51-SOFP!J51 -> 2070189
K23: =SUM(K21:K22) -> 11694994 | M23: =SUM(M21:M22) -> 13432314 | O23: =SUM(O21:O22) -> 2070189
C25: Drawings | K25: =NOTES!L231 -> -61005627 | M25: =NOTES!N231 -> -53110013 | O25: =NOTES!P231 -> -46236284
K26: =SUM(K25) -> -61005627 | M26: =SUM(M25) -> -53110013 | O26: =SUM(O25) -> -46236284
A28: Net cash generated from operating activities | K28: =+K13+K19+K23+K26 -> 28079661 | M28: =+M13+M19+M23+M26 -> 8657167.4 | O28: =+O13+O19+O23+O26 -> 2137826
A30: CASH FLOWS FROM INVESTING ACTIVITIES
B31: Purchase of property, plant and equipment | K31: 0 | M31: 0 | O31: 0
A32: Net cash generated from investing activities | K32: =SUM(K31:K31) -> 0 | M32: =SUM(M31:M31) -> 0 | O32: =SUM(O31:O31) -> 0
A34: CASH FLOWS FROM FINANCING ACTIVITIES
B35: Non Current Liability | K35: -4344523 | M35: =SOFP!F41 -> 39280373 | O35: 0
B36: Capital | K36: 0 | M36: 0 | O36: 0
A37: Net cash generated from financing activities | K37: =SUM(K35:K36) -> -4344523 | M37: =SUM(M35:M36) -> 39280373 | O37: =SUM(O35:O36) -> 0
A39: NET (DECREASE) / INCREASE IN CASH AND CASH EQUIVALENTS | K39: =+K28+K32+K37 -> 23735138 | M39: =+M28+M32+M37 -> 47937540 | O39: =+O28+O32+O37 -> 2137826
A40: CASH AND CASH EQUIVALENTS AT BEGINNING OF THE YEAR | K40: =M41 -> 61683695 | M40: =O41 -> 13746153 | O40: =SOFP!J23 -> 11608328
A41: CASH AND CASH EQUIVALENTS AT END OF THE YEAR | K41: =K39+K40 -> 85418833 | M41: =M39+M40+2 -> 61683695 | O41: =O39+O40-1 -> 13746153
A42: ='P & L'!A33 -> The annexed notes form an integral part of these financial statements.
M51: PROPRIETOR
P73: 91381500
N74: 91381,500 3,600,000 500,000 800,000 709,300
N84: 800000
P228: =SUM(P227:P227) -> 0

Sheet Policies FC
A2: ='P & L'!A1 -> AIMAL KHAN TRADERS
A3: NOTES TO THE FINANCIAL STATEMENTS
A4: ='P & L'!A3 -> FOR THE YEAR ENDED DECEMBER 31, 2025
A6: 1 | B6: FIRM AND ITS OPERATION
C8: Legal status and operations
C10: "M/S AIMAL KHAN TRADERS" is a registered business concern engaged in the business of Distribution of National Products in KPK.
A14: 2 | B14: STATEMENT OF COMPLIANCE | Q14: SIGNIFICANT ACCOUNTING POLICIES
C16: These financial statements have been prepared in accordance with the accounting and reporting standards as applicable in Pakistan. The accounting and reporting standards applicable in Pakistan comprise of:
C18: - | D18: Revised Accounting and Financial Reporting Standard for the Small -Sized Entities (Revised AFRS for SSEs) issued by the Institute of Chartered Accountants of Pakistan as notified under the Companies Act, 2017; and
C20: - | D20: Provisions of and directives issued under the Companies Act , 2017.
C22: Where provisions of and directives issued under the Companies Act, 2017 differ from the Revised AFRS for SSEs, the provisions of and directives issued under the Companies Act, 2017 have been followed.
A24: =A6+1 -> 2 | B24: 'BASIS OF PREPARATION
B26: =A24+0.1 -> 2.1 | C26: Statement of compliance
C28: These financial statements have been prepared in accordance with the accounting and financial reporting standards as applicable in Pakistan. The accounting and financial reporting standards as applicable in Pakistan comprise of:
B30: =B26+0.1 -> 2.2 | C30: Basis of measurement
C31: These financial statements have been prepared under the historical cost convention, except for certain items as disclosed in the relevant accounting policies below.
B33: =B30+0.1 -> 2.3 | C33: Functional and presentation currency
C35: These financial statements are presented in Pakistani Rupees which is also the firm’s functional currency. All financial information presented in Pakistani Rupees has been rounded to nearest rupee, unless otherwise indicated.
B37: =B33+0.1 -> 2.4 | C37: Key judgments, estimates and assumptions
C39: The preparation of financial statements in conformity with the accounting and reporting standards as applicable in Pakistan requires the use of certain critical accounting estimates. In addition, it requires management to exercise judgement in the process of applying the firm's accounting policies. The areas involving a high degree of judgement or complexity, or areas where assumptions and estimates are significant to the financial statements, are documented in the relevant accounting policies and notes.
C41: The revisions to ·accounting estimates (if any) are recognized in the period in which the estimate is revised i f the revision affects only that period or in the period of the revision and future periods if the revision affects both current and future periods.
C45: IAS-1 | E45: Presentation of Financial Statements – Presentation of items of other comprehensive income (Amendment)
C46: IAS-12 | E46: Income Taxes - Recovery of Underlying Assets (Amendment)
C48: The adoption of the above amendments did not have any material effect on these financial statements.
A49: =A24+1 -> 3 | B49: SUMMARY OF SIGNIFICANT ACCOUNTING POLICIES
C51: The significant accounting policies set out below have been applied consistently to all periods presented in these financial statements, unless otherwise stated.
C53: Deferred taxation is provided on all temporary timing differences by using the balance sheet method.
C55: Deferred income tax asset is recognized for all deductible temporary differences, carry-forward unused tax credits and unused tax losses, to the extent that it is probable that taxable profit will be available against which the deductible temporary differences, carry-forward of unused tax credits and unused tax losses can be utilized.
C57: Deferred tax liabilities are generally recognized for all taxable temporary differences .
C58: The carrying amount of deferred income tax assets is reviewed at each statement of financial position date and reduced to the extent that it is no longer probable that sufficient taxable profit will be available to allow all or part of the deferred income tax assets to be utilized.
C59: Deferred tax assets and liabilities are measured at the tax rates that are expected to apply to the period when the liability is settled based on tax rates that have been enacted or substantively enacted at the statement of financial position date.
B60: =#REF!+0.1 -> #REF! | C60: Staff retirement benefits | N60: 91381500
L61: 91381,500 3,600,000 500,000 800,000 709,300
C62: The firm operates un-recognized provident fund for its permanent employees. Equal monthly contribution by the employer and the employees at the rate of 5% of the basic salary is being made.
B64: =A49+0.1 -> 3.1 | C64: Property, plant and equipment
C68: o | D68: These are stated at cost less accumulated depreciation and impairment loss, if any.
C70: o | D70: Depreciation is calculated using reducing balance method at the rates stated in note 4. Depreciation charge commences from the month in which asset is available for use and continues until themonth of disposal.
L71: 800000
C72: o | D72: Useful lives, methods and rates of depreciation and residual values are reviewed and adjusted, if appropriate on regular basis. Any change in estimates in future years might affect the carrying amounts of the respective items of property, plant and equipment.
C73: =C72 -> o | D73: Normal repairs and maintenance is charged to revenue as and when incurred, while major renewals and replacements are capitalized.
...

Sheet FA-04
A2: 4 | B2: PROPERTY AND EQUIPMENT- Tangible | D2: 2021 | F2: 2020
D3: Rupees | F3: Rupees
B5: Property and equipments (Note 4.1) | D5: =L195 -> 7918840.9 | F5: 850000
A8: =A2+0.1 -> 4.1 | B8: Reconciliation of carrying amounts at the beginning and end of the year is as follows:
D10: Owned | J10: Leased | L10: Total
D11: Land & Building | F11: Furniture & Fixtures | H11: Plant & Machinery | J11: Vehicles
D12: ------------------------------------------------------------------- Rupees ----------------------------------------------------------------------
B13: Year ended 30 June 2011
B14: Opening net book value | D14: 31563 | F14: 9879 | G14: 0 | H14: 48719 | L14: 44127890
B15: Additions | D15: 0 | F15: 0 | H15: 243958 | L15: 72132365
B16: Transfers | D16: 0 | F16: 0 | H16: 0 | L16: -1456875
B17: Adjustments | D17: 0 | F17: 0 | H17: 0 | L17: 0
B18: Disposal (at NBV) | D18: 0 | F18: 0 | H18: 0 | L18: 0
L19: 0
B20: Depreciation | D20: -4735 | F20: -1482 | H20: -18635 | L20: -14559477
D21: 26828 | F21: 8397 | G21: 0 | H21: 274042 | L21: 100243903
B22: Closing net book value
B24: At 30 June 2011
B25: Cost | D25: 34850 | F25: 12557 | G25: 0 | H25: 308958 | L25: 125912076
B26: Accumulated depreciation | D26: -8022 | F26: -4160 | G26: 0 | H26: -34916 | L26: -25668173
B27: Net book value | D27: 26828 | F27: 8397 | H27: 274042 | L27: 100243903
B29: Year ended 30 June 2012
B30: Opening net book value | D30: 26828 | F30: 8397 | G30: 0 | H30: 274042 | L30: =SUM(D30:H30) -> 309267
B31: Additions | D31: 0 | F31: 0 | H31: 742593 | L31: =SUM(D31:H31) -> 742593
B33: Depreciation | D33: -4024.2 | F33: -1259.55 | H33: -65217 | L33: -17337122
B35: Closing net book value | D35: =D30+D31+D33 -> 22803.8 | F35: =F30+F31+F33 -> 7137.45 | H35: =H30+H31+H33 -> 951418 | L35: =L30+L31+L33 -> -16285262
B37: At 30 June 2012
B39: Cost | D39: 34850 | F39: 12557 | G39: 0 | H39: 1051551 | L39: =SUM(D39:H39) -> 1098958
B40: Accumulated depreciation | D40: -12046.2 | F40: -5419.55 | G40: 0 | H40: -100133 | L40: =SUM(D40:H40) -> -117598.75
B41: Net book value | D41: =SUM(D39:D40) -> 22803.8 | F41: =SUM(F39:F40) -> 7137.45 | H41: =SUM(H39:H40) -> 951418 | L41: =SUM(L39:L40) -> 981359.25
B43: Year ended 30 June 2013
B44: Opening net book value | D44: =+D41 -> 22803.8 | F44: =+F41 -> 7137.45 | G44: 0 | H44: =+H41 -> 951418 | L44: =SUM(D44:H44) -> 981359.25
B45: Additions | D45: 28854 | F45: 0 | H45: 683430 | L45: =SUM(D45:H45) -> 712284
B47: Depreciation | D47: -7749 | F47: -1070 | H47: -175678 | L47: =SUM(D47:H47) -> -184497
B49: Closing net book value | D49: =SUM(D44:D47) -> 43908.8 | F49: =SUM(F44:F47) -> 6067.45 | H49: =SUM(H44:H47) -> 1459170 | L49: =SUM(L44:L47) -> 1509146.2
B51: At 30 June 2013
B53: Cost | D53: =D39+D45 -> 63704 | F53: =F39+F45 -> 12557 | G53: 0 | H53: =H39+H45 -> 1734981 | L53: =SUM(D53:H53) -> 1811242
B54: Accumulated depreciation | D54: =+D40+D47 -> -19795.2 | F54: =+F40+F47 -> -6489.55 | G54: 0 | H54: =+H40+H47 -> -275811 | L54: =SUM(D54:H54) -> -302095.75
B55: Net book value | D55: =SUM(D53:D54) -> 43908.8 | F55: =SUM(F53:F54) -> 6067.45 | H55: =SUM(H53:H54) -> 1459170 | L55: =SUM(L53:L54) -> 1509146.2
B57: Year ended 30 June 2014
...

Sheet Note 5 '2025
A1: 5 | B1: FIXED ASSETS
B3: PARTICULARS | C3: COST | F3: Rate% | G3: DEPRECIATION | J3: W.D.V As at 31/12/2025
C4: As at 1/1/2025 | D4: Additions / Deletions | E4: As at 31/12/2025 | G4: As at 1/1/2025 | H4: For the Year | I4: As at 31/12/2025
B6: Office Decoration | C6: 1503162 | D6: 0 | E6: =+C6+D6 -> 1503162 | F6: 0.1 | G6: 704320 | H6: =(E6-G6)*0.1 -> 79884.2 | I6: =+G6+H6 -> 784204.2 | J6: =+E6-I6 -> 718957.8
B7: Motor Vehicles | C7: 9469948 | E7: =+C7+D7 -> 9469948 | F7: 0.1 | G7: 3943332 | H7: =(E7-G7)*0.1 -> 552661.6 | I7: =+G7+H7 -> 4495993.6 | J7: =+E7-I7 -> 4973954.4
B8: Furniture & Fixtures | C8: 354122 | D8: 0 | E8: =+C8+D8 -> 354122 | F8: 0.1 | G8: 141232 | H8: =(E8-G8)*0.1 -> 21289 | I8: =+G8+H8 -> 162521 | J8: =+E8-I8 -> 191601
B9: Computer & Electric Equipments | C9: 192550 | E9: =+C9+D9 -> 192550 | F9: 0.1 | G9: 90229 | H9: =(E9-G9)*0.1 -> 10232.1 | I9: =+G9+H9 -> 100461.1 | J9: =+E9-I9 -> 92088.9
B10: Other Assets | C10: 65835 | D10: 0 | E10: =+C10+D10 -> 65835 | F10: 0.1 | G10: 30848 | H10: =(E10-G10)*0.1 -> 3498.7 | I10: =+G10+H10 -> 34346.7 | J10: =+E10-I10 -> 31488.3
B11: 2025 | C11: =SUM(C6:C10) -> 11585617 | D11: =SUM(D6:D10) -> 0 | E11: =SUM(E6:E10) -> 11585617 | G11: =SUM(G6:G10) -> 4909961 | H11: =SUM(H6:H10) -> 667565.6 | I11: =SUM(I6:I10) -> 5577526.6 | J11: =SUM(J6:J10) -> 6008090.4
B13: 2024 | C13: =+C11 -> 11585617 | E13: =+C13 -> 11585617 | G13: 4168221 | H13: 741740 | I13: =+G13+H13 -> 4909961 | J13: =+C13-I13 -> 6675656
A15: 5.1 | B15: Deprecation for the year has been allocated as under:
G16: 2025 | H16: 2024
G17: Rupees | H17: Rupees
D18: Cost of Sales | G18: =H11*0.8 -> 534052.48 | H18: =H13*0.8 -> 593392
D19: Operating Expenses | G19: =H11*0.2 -> 133513.12 | H19: =H13*0.2 -> 148348
G20: =SUM(G18:G19) -> 667565.6 | H20: =SUM(H18:H19) -> 741740

Sheet NOTES
A1: =SOFP!A1 -> AIMAL KHAN TRADERS
A2: ='Policies FC'!A3:N3 -> NOTES TO THE FINANCIAL STATEMENTS
A3: ='Policies FC'!A4 -> FOR THE YEAR ENDED DECEMBER 31, 2025
A5: 1 | B5: COMPANY AND ITS OPERATION
C7: Legal status and operations
C9: Food Caravan (Pvt) Limited was incorporated in Pakistan on October 5, 2018 under the Companies Act, 2017 on May 30, 2017 as a private company limited by shares and is engaged in the business of provision of food. The registered office of the company is situated at 435K-Block Model town Lahore, whereas the location of principal place of its business is situated at CCA 237, Sector FF, Phase IV Commercial, DHA, Lahore.
B11: =B7+0.1 -> 0.1 | C11: Summary of significant events and transactions in the current reporting period.
C13: The Third and Fifth Schedules to the Companies Act, 2017 became applicable to the Company for the first time for the preparation of these financial statements. The Companies Act, 2017 (including its Third and Fifth Schedule) forms an integral part of the statutory financial reporting framework applicable to the Company and amongst others, prescribes the nature and content of disclosures in relation to various elements of the financial statements. Additional disclosures include but are not limited to, additional disclosure requirements for related parties (refer note 21) and management assessment of sufficiency of tax provision in the financial statements (refer note 18), etc.
A15: 2 | B15: STATEMENT OF COMPLIANCE
C17: These financial statements have been prepared in accordance with the accounting and reporting standards as applicable in Pakistan. The accounting and reporting standards applicable in Pakistan comprise of:
C19: - | D19: Revised Accounting and Financial Reporting Standard for the Small -Sized Entities (Revised AFRS for SSEs) issued by the Institute of Chartered Accountants of Pakistan as notified under the Companies Act, 2017; and
C21: - | D21: Provisions of and directives issued under the Companies Act , 2017.
C23: Where provisions of and directives issued under the Companies Act, 2017 differ from the Revised AFRS for SSEs, the provisions of and directives issued under the Companies Act, 2017 have been followed.
A25: =A5+1 -> 2 | B25: BASIS OF PREPARATION
B27: =A25+0.1 -> 2.1 | C27: Accounting convention
C29: These financial statements have been prepared under the historical cost convention without any adjustment for inflation or current values. In these financial statements, except for cash flow statement, all the transactions have been accounted for on accrual basis.
B31: =B27+0.1 -> 2.2 | C31: Functional and presentation currency
B35: =B31+0.1 -> 2.3 | C35: Key judgments, estimates and assumptions
C37: The preparation of financial statements in conformity with Revised AFRS for SSEs requires management to make judgments, estimates and assumptions that affect the application of policies and reported amounts of assets and liabilities, income and expenses. The estimates and associated assumptions are based on historical experience and various other factors that are believed to be reasonable under the circumstances, the results of which form the basis of making the judgments about carrying values of assets and liabilities that are not readily apparent from other sources. Actual results may differ from these estimates.
C39: The estimates and underline assumptions are reviewed on an on going basis. Revisions to accounting estimates are recognized in the period in which the estimates are revised.
C42: Significant areas requiring the use of the management estimates in these financial statements relates to the useful lives and residual values of the property, plant and equipment, provision for doubtful debts on account receivables, estimation of contingencies, and estimation of taxation. However, assumptions and judgments made by management in the application of accounting policies that have significant effect on the financial statements are not expected to result in material adjustment to the carrying amounts of assets and liabilities in the next year.
C48: IAS-1 | E48: Presentation of Financial Statements – Presentation of items of other comprehensive income (Amendment)
C49: IAS-12 | E49: Income Taxes - Recovery of Underlying Assets (Amendment)
C51: The adoption of the above amendments did not have any material effect on these financial statements.
A52: =A25+1 -> 3 | B52: SUMMARY OF SIGNIFICANT ACCOUNTING POLICIES
B54: The significant accounting policies set out below have been applied consistently to all periods presented in these financial statements, unless otherwise stated.
B56: =A52+0.1 -> 3.1 | C56: Taxation
C58: Current
C60: The current taxation is computed on the basis of profit for the year adjusted for fiscal purposes after taking into account the tax credit or rebate, if any or Alternative Corporate Tax @ 17% of accounting income u/s 113 C of the Income Tax Ordinance, 2001 or minimum tax u/s 113 of the Income Tax Ordinance, 2001, whichever is higher.
C62: Deferred | P62: 91381500
N63: 91381,500 3,600,000 500,000 800,000 709,300
C64: The accounting standards applicable to size and stature of the company do not require the recognition of deferred tax. Accordingly deferred tax (asset)/liability is not recognized in these financial statements being not applicable in the instant case.
C65: Deferred taxation is provided on all temporary timing differences by using the balance sheet method.
C67: Deferred income tax asset is recognized for all deductible temporary differences, carry-forward unused tax credits and unused tax losses, to the extent that it is probable that taxable profit will be available against which the deductible temporary differences, carry-forward of unused tax credits and unused tax losses can be utilized.
C69: Deferred tax liabilities are generally recognized for all taxable temporary differences .
C70: The carrying amount of deferred income tax assets is reviewed at each statement of financial position date and reduced to the extent that it is no longer probable that sufficient taxable profit will be available to allow all or part of the deferred income tax assets to be utilized.
C71: Deferred tax assets and liabilities are measured at the tax rates that are expected to apply to the period when the liability is settled based on tax rates that have been enacted or substantively enacted at the statement of financial position date.
N72: 500000
B73: =B56+0.1 -> 3.2 | C73: Staff retirement benefits | N73: 800000
N74: 709300
...

Sheet Trial Balance
C1: AIMAL KHAN TRADERS
C2: Trial Balance As At 9 june 2026
B3: Account Name | C3: Debit (Dr) | D3: Credit (Cr)
B4: Fixed Assets - Cost | C4: ='Note 5 ''2025'!C11 -> 11585617
B5: Accumulated Depreciation | D5: ='Note 5 ''2025'!I11 -> 5577526.6
B6: Stores and Spares | C6: =NOTES!L203 -> 85471121
B7: Trade Receivables | C7: =SOFP!D21 -> 77671960
B8: Advances, Deposits & Other Receivables | C8: =NOTES!L213 -> 24183427
B9: Cash and Bank Balances | C9: =NOTES!L219 -> 85418833
B10: Capital Account | D10: =NOTES!L227 -> 1.5258328e+08
B11: Drawings | C11: =NOTES!L231*-1 -> 61005627
B12: Retained Earnings (True Opening Balance)
B13: Long-Term Financing / Loans | D13: =NOTES!L251+NOTES!L270 -> 39280373
B14: Creditors, Accrued Exp. & Other Liab. | D14: =NOTES!L279 -> 44566142
B15: Revenue - Net | D15: =NOTES!L282 -> 8.2445869e+08
B16: Cost of Revenue | C16: =NOTES!L302 -> 6.7175285e+08
B17: Administrative Expenses | C17: =NOTES!L318 -> 32608624
B18: Financial Charges | C18: =NOTES!L337 -> 1327944.7
B19: Taxation for the Year | C19: ='P & L'!J21 -> 15440005
B20: TOTALS | C20: =SUM(C4:C19) -> 1.066466e+09 | D20: =SUM(D4:D19) -> 1.066466e+09 | E20: =D20-C20 -> 0

Sheet Loan
A1: LOAN AMORTISATION SCHEDULE
A2: Loan 1 | M2: Loan 2
A3: 7500000 | M3: 7000000
A4: 0.07 | M4: 0.09
A5: Date | B5: Total Amount | C5: Principal | D5: Interest | E5: Outstanding | F5: Payable | I5: Paid | M5: Date | N5: Total Amount | O5: Principal | P5: Interest | Q5: Outstanding | R5: Payable | U5: Paid
A6: 45457 | B6: 0 | C6: 0 | D6: 0 | E6: 7500000 | M6: 45448 | N6: 0 | O6: 0 | P6: 0 | Q6: 7000000
A7: 45474 | B7: 149385.25 | C7: 125000 | D7: 24385.25 | E7: =+E6-C7 -> 7375000 | M7: 45478 | N7: =+O7+P7 -> 246083.34 | O7: 194444 | P7: 51639.34 | Q7: =+Q6-O7 -> 6805556
A8: 45505 | B8: 168726.09 | C8: 125000 | D8: 43726.09 | E8: =+E7-C8 -> 7250000 | M8: 45509 | N8: =+O8+P8 -> 246322.42 | O8: 194444 | P8: 51878.42 | Q8: =+Q7-O8 -> 6611112
A9: 45536 | B9: =+C9+D9 -> 167984.97 | C9: 125000 | D9: 42984.97 | E9: =+E8-C9 -> 7125000 | M9: 45540 | N9: =+O9+P9 -> 244840.18 | O9: 194444 | P9: 50396.18 | Q9: =+Q8-O9 -> 6416668
A10: 45566 | B10: =+C10+D10 -> 165881.15 | C10: 125000 | D10: 40881.15 | E10: =+E9-C10 -> 7000000 | M10: 45570 | N10: =+O10+P10 -> 241780.08 | O10: 194444 | P10: 47336.08 | Q10: =+Q9-O10 -> 6222224
A11: 45597 | B11: =+C11+D11 -> 166502.73 | C11: 125000 | D11: 41502.73 | E11: =+E10-C11 -> 6875000 | I11: Year 2024 | M11: 45601 | N11: =+O11+P11 -> 241875.71 | O11: 194444 | P11: 47431.71 | Q11: =+Q10-O11 -> 6027780 | U11: Year 2024
A12: 45627 | B12: =+C12+D12 -> 164446.72 | C12: 125000 | D12: 39446.72 | E12: =+E11-C12 -> 6750000 | I12: Interest | J12: Principal | M12: 45631 | N12: =+O12+P12 -> 238911.23 | O12: 194444 | P12: 44467.23 | Q12: =+Q11-O12 -> 5833336 | U12: Interest | V12: Principal
A13: 45658 | B13: =+C13+D13 -> 165020.49 | C13: 125000 | D13: 40020.49 | E13: =+E12-C13 -> 6625000 | I13: =SUM(D7:D13) -> 272947.4 | J13: =SUM(C7:C13) -> 875000 | M13: 45662 | N13: =+O13+P13 -> 238926.95 | O13: 194444 | P13: 44482.95 | Q13: =+Q12-O13 -> 5638892 | U13: =SUM(P7:P13) -> 337631.91 | V13: =SUM(O7:O13) -> 1361108
A14: 45689 | B14: =+C14+D14 -> 164388.99 | C14: 125000 | D14: 39388.99 | E14: =+E13-C14 -> 6500000 | M14: 45693 | N14: =+O14+P14 -> 237546.76 | O14: 194444 | P14: 43102.76 | Q14: =+Q13-O14 -> 5444448
A15: 45717 | B15: =+C15+D15 -> 159904.11 | C15: 125000 | D15: 34904.11 | E15: =+E14-C15 -> 6375000 | M15: 45721 | N15: =+O15+P15 -> 232033.07 | O15: 194444 | P15: 37589.07 | Q15: =+Q14-O15 -> 5250004
A16: 45748 | B16: =+C16+D16 -> 162900.68 | C16: 125000 | D16: 37900.68 | E16: =+E15-C16 -> 6250000 | M16: 45752 | N16: =+O16+P16 -> 234574.17 | O16: 194444 | P16: 40130.17 | Q16: =+Q15-O16 -> 5055560
A17: 45778 | B17: =+C17+D17 -> 160958.8 | C17: 125000 | D17: 35958.8 | E17: =+E16-C17 -> 6125000 | M17: 45782 | N17: =+O17+P17 -> 231841.29 | O17: 194444 | P17: 37397.29 | Q17: =+Q16-O17 -> 4861116
A18: 45809 | B18: =+C18+D18 -> 161414.38 | C18: 125000 | D18: 36414.38 | E18: =+E17-C18 -> 6000000 | M18: 45813 | N18: =+O18+P18 -> 231601.57 | O18: 194444 | P18: 37157.57 | Q18: =+Q17-O18 -> 4666672
A19: 45839 | B19: =+C19+D19 -> 159520.55 | C19: 125000 | D19: 34520.55 | E19: =+E18-C19 -> 5875000 | M19: 45843 | N19: =+O19+P19 -> 228964.59 | O19: 194444 | P19: 34520.59 | Q19: =+Q18-O19 -> 4472228
A20: 45870 | B20: =+C20+D20 -> 159928.08 | C20: 125000 | D20: 34928.08 | E20: =+E19-C20 -> 5750000 | M20: 45874 | N20: =+O20+P20 -> 228628.98 | O20: 194444 | P20: 34184.98 | Q20: =+Q19-O20 -> 4277784
A21: 45901 | B21: =+C21+D21 -> 159184.93 | C21: 125000 | D21: 34184.93 | E21: =+E20-C21 -> 5625000 | M21: 45905 | N21: =+O21+P21 -> 227142.68 | O21: 194444 | P21: 32698.68 | Q21: =+Q20-O21 -> 4083340
A22: 45931 | B22: =+C22+D22 -> 157363.01 | C22: 125000 | D22: 32363.01 | E22: =+E21-C22 -> 5500000 | M22: 45935 | N22: =+O22+P22 -> 224649.53 | O22: 194444 | P22: 30205.53 | Q22: =+Q21-O22 -> 3888896
A23: 45962 | B23: =+C23+D23 -> 157698.63 | C23: 125000 | D23: 32698.63 | E23: =+E22-C23 -> 5375000 | F23: Year 2024 | I23: Year 2025 | M23: 45966 | N23: =+O23+P23 -> 224170.08 | O23: 194444 | P23: 29726.08 | Q23: =+Q22-O23 -> 3694452 | R23: Year 2024 | U23: Year 2025
A24: 45992 | B24: =+C24+D24 -> 155469.18 | C24: 125000 | D24: 30469.18 | E24: =+E23-C24 -> 5250000 | F24: Principal | G24: Interest | I24: Interest | J24: Principal | M24: 45996 | N24: =+O24+P24 -> 221772.82 | O24: 194444 | P24: 27328.82 | Q24: =+Q23-O24 -> 3500008 | R24: Principal | S24: Interest | U24: Interest | V24: Principal
A25: 46023 | B25: =+C25+D25 -> 156212.33 | C25: 125000 | D25: 31212.33 | E25: =+E24-C25 -> 5125000 | F25: =+E13-E25 -> 1500000 | G25: =SUM(D14:D25) -> 414943.67 | H25: CL | I25: =SUM(D14:D25) -> 414943.67 | J25: =SUM(C14:C25) -> 1500000 | M25: 46027 | N25: =+O25+P25 -> 221197.49 | O25: 194444 | P25: 26753.49 | Q25: =+Q24-O25 -> 3305564 | R25: =+Q13-Q25 -> 2333328 | S25: =SUM(P14:P25) -> 410795.03 | T25: CL | U25: =SUM(P14:P25) -> 410795.03 | V25: =SUM(O14:O25) -> 2333328
A26: 46054 | B26: =+C26+D26 -> 155469.18 | C26: 125000 | D26: 30469.18 | E26: =+E25-C26 -> 5000000 | F26: =+E25 -> 5125000 | G26: =SUM(D26:D66) -> 627389.65 | H26: NCL | M26: 46058 | N26: =+O26+P26 -> 219711.19 | O26: 194444 | P26: 25267.19 | Q26: =+Q25-O26 -> 3111120 | R26: =+Q25 -> 3305564 | S26: =SUM(P26:P42) -> 222419.33 | T26: NCL
A27: 46082 | B27: =+C27+D27 -> 151849.32 | C27: 125000 | D27: 26849.32 | E27: =+E26-C27 -> 4875000 | M27: 46086 | N27: =+O27+P27 -> 215923.51 | O27: 194444 | P27: 21479.51 | Q27: =+Q26-O27 -> 2916676
A28: 46113 | B28: =+C28+D28 -> 153982.88 | C28: 125000 | D28: 28982.88 | E28: =+E27-C28 -> 4750000 | M28: 46117 | N28: =+O28+P28 -> 216738.59 | O28: 194444 | P28: 22294.59 | Q28: =+Q27-O28 -> 2722232
A29: 46143 | B29: =+C29+D29 -> 152328.77 | C29: 125000 | D29: 27328.77 | E29: =+E28-C29 -> 4625000 | M29: 46147 | N29: =+O29+P29 -> 214581.06 | O29: 194444 | P29: 20137.06 | Q29: =+Q28-O29 -> 2527788
A30: 46174 | B30: =+C30+D30 -> 152498.58 | C30: 125000 | D30: 27498.58 | E30: =+E29-C30 -> 4500000 | M30: 46178 | N30: =+O30+P30 -> 213766 | O30: 194444 | P30: 19322 | Q30: =+Q29-O30 -> 2333344
A31: 46204 | B31: =+C31+D31 -> 150890.41 | C31: 125000 | D31: 25890.41 | E31: =+E30-C31 -> 4375000 | M31: 46208 | N31: =+O31+P31 -> 211704.35 | O31: 194444 | P31: 17260.35 | Q31: =+Q30-O31 -> 2138900
A32: 46235 | B32: =+C32+D32 -> 151010.27 | C32: 125000 | D32: 26010.27 | E32: =+E31-C32 -> 4250000 | M32: 46239 | N32: =+O32+P32 -> 210793.4 | O32: 194444 | P32: 16349.4 | Q32: =+Q31-O32 -> 1944456
A33: 46266 | B33: =+C33+D33 -> 150267.12 | C33: 125000 | D33: 25267.12 | E33: =+E32-C33 -> 4125000 | M33: 46270 | N33: =+O33+P33 -> 209307.1 | O33: 194444 | P33: 14863.1 | Q33: =+Q32-O33 -> 1750012
A34: 46296 | B34: =+C34+D34 -> 148732.88 | C34: 125000 | D34: 23732.88 | E34: =+E33-C34 -> 4000000 | M34: 46300 | N34: =+O34+P34 -> 207389.29 | O34: 194444 | P34: 12945.29 | Q34: =+Q33-O34 -> 1555568
A35: 46327 | B35: =+C35+D35 -> 148780.82 | C35: 125000 | D35: 23780.82 | E35: =+E34-C35 -> 3875000 | F35: Year 2025 | M35: 46331 | N35: =+O35+P35 -> 206334.51 | O35: 194444 | P35: 11890.51 | Q35: =+Q34-O35 -> 1361124 | R35: Year 2025
A36: 46357 | B36: =+C36+D36 -> 147294.52 | C36: 125000 | D36: 22294.52 | E36: =+E35-C36 -> 3750000 | F36: Principal | G36: Interest | M36: 46361 | N36: =+O36+P36 -> 204512.59 | O36: 194444 | P36: 10068.59 | Q36: =+Q35-O36 -> 1166680 | R36: Principal | S36: Interest
A37: 46388 | B37: =+C37+D37 -> 147294.52 | C37: 125000 | D37: 22294.52 | E37: =+E36-C37 -> 3625000 | F37: =+E25-E37 -> 1500000 | G37: =SUM(D26:D37) -> 310399.27 | H37: CL | M37: 46392 | N37: =+O37+P37 -> 203361.91 | O37: 194444 | P37: 8917.91 | Q37: =+Q36-O37 -> 972236 | R37: =+Q25-Q37 -> 2333328 | S37: =SUM(P26:P37) -> 200795.5 | T37: CL
A38: 46419 | B38: =+C38+D38 -> 146651.37 | C38: 125000 | D38: 21651.37 | E38: =+E37-C38 -> 3500000 | F38: =+E37 -> 3625000 | G38: =SUM(D38:D66) -> 316990.38 | H38: NCL | M38: 46423 | N38: =+O38+P38 -> 201875.61 | O38: 194444 | P38: 7431.61 | Q38: =+Q37-O38 -> 777792 | R38: =+Q37 -> 972236 | S38: =SUM(P38:P42) -> 21623.83 | T38: NCL
A39: 46447 | B39: =+C39+D39 -> 143794.52 | C39: 125000 | D39: 18794.52 | E39: =+E38-C39 -> 3375000 | M39: 46451 | N39: =+O39+P39 -> 199813.96 | O39: 194444 | P39: 5369.96 | Q39: =+Q38-O39 -> 583348
A40: 46478 | B40: =+C40+D40 -> 145065.07 | C40: 125000 | D40: 20065.07 | E40: =+E39-C40 -> 3250000 | M40: 46482 | N40: =+O40+P40 -> 198903.02 | O40: 194444 | P40: 4459.02 | Q40: =+Q39-O40 -> 388904
...

Sheet Note 5
A1: 5 | B1: FIXED ASSETS
B3: PARTICULARS | C3: COST | F3: Rate% | G3: DEPRECIATION | J3: W.D.V As at 31/12/2024
C4: As at 1/1/2024 | D4: Additions / Deletions | E4: As at 31/12/2024 | G4: As at 1/1/2024 | H4: For the Year | I4: As at 31/12/2024
B6: Office Decoration | C6: 1503162 | D6: 0 | E6: =+C6+D6 -> 1503162 | F6: 0.1 | G6: 615560 | H6: =(E6-G6)*0.1 -> 88760.2 | I6: =+G6+H6 -> 704320.2 | J6: =+E6-I6 -> 798841.8
B7: Motor Vehicles | C7: 9469948 | E7: =+C7+D7 -> 9469948 | F7: 0.1 | G7: 3329263 | H7: =(E7-G7)*0.1 -> 614068.5 | I7: =+G7+H7 -> 3943331.5 | J7: =+E7-I7 -> 5526616.5
B8: Furniture & Fixtures | C8: 354122 | D8: 0 | E8: =+C8+D8 -> 354122 | F8: 0.1 | G8: 117578 | H8: =(E8-G8)*0.1 -> 23654.4 | I8: =+G8+H8 -> 141232.4 | J8: =+E8-I8 -> 212889.6
B9: Computer & Electric Equipments | C9: 192550 | E9: =+C9+D9 -> 192550 | F9: 0.1 | G9: 78860 | H9: =(E9-G9)*0.1 -> 11369 | I9: =+G9+H9 -> 90229 | J9: =+E9-I9 -> 102321
B10: Other Assets | C10: 65835 | D10: 0 | E10: =+C10+D10 -> 65835 | F10: 0.1 | G10: 26960 | H10: =(E10-G10)*0.1 -> 3887.5 | I10: =+G10+H10 -> 30847.5 | J10: =+E10-I10 -> 34987.5
B11: 2024 | C11: =SUM(C6:C10) -> 11585617 | D11: =SUM(D6:D10) -> 0 | E11: =SUM(E6:E10) -> 11585617 | G11: =SUM(G6:G10) -> 4168221 | H11: =SUM(H6:H10) -> 741739.6 | I11: =SUM(I6:I10) -> 4909960.6 | J11: =SUM(J6:J10) -> 6675656.4
J12: \
B13: 2023 | C13: =+C11 -> 11585617 | E13: =+C13 -> 11585617 | G13: 3344066 | H13: 824155 | I13: =+G13+H13 -> 4168221 | J13: =+C13-I13 -> 7417396
A15: 5.1 | B15: Deprecation for the year has been allocated as under:
G16: 2025 | H16: 2024 | I16: 2023
G17: Rupees | H17: Rupees | I17: Rupees
C18: Cost of Sales | H18: =H11*0.8 -> 593391.68 | I18: =H13*0.8 -> 659324
C19: Operating Expenses | H19: =H11*0.2 -> 148347.92 | I19: =H13*0.2 -> 164831
G20: =SUM(G18:G19) -> 0 | H20: =SUM(H18:H19) -> 741739.6 | I20: =SUM(I18:I19) -> 824155

Sheet DEP 2017
A4: 3. | B4: FIXED ASSETS
B6: P A R T I C U L A R S | D6: C O S T | G6: Rate (%) | H6: D E P R E C I A T I O N | L6: W.D.V
D7: As at 01-04-2022 | E7: Additions | F7: As at 31-03-2023 | H7: =D7 -> As at 01-04-2022 | I7: For the year | J7: =F7 -> As at 31-03-2023 | L7: =J7 -> As at 31-03-2023
B11: Residential House (Street No. 4 Gujrat) | D11: 45000000 | F11: =+D11+E11 -> 45000000 | H11: 0 | J11: =SUM(H11:I11) -> 0 | L11: =+F11-J11 -> 45000000
B12: Residential House (DHA, Rawalpindi) | D12: 47000000 | F12: =+D12+E12 -> 47000000 | H12: 0 | J12: =SUM(H12:I12) -> 0 | L12: =+F12-J12 -> 47000000
B13: Residential House (Kathala Chenab) | D13: 15000000 | F13: =+D13+E13 -> 15000000 | H13: 0 | J13: =SUM(H13:I13) -> 0 | L13: =+F13-J13 -> 15000000
B14: Poultry Farm (Control Shed) | D14: 22000000 | F14: =+D14+E14 -> 22000000 | L14: =+F14-J14 -> 22000000
B15: Office Building (3264-sq.ft.) | D15: 9000000 | F15: =+D15+E15 -> 9000000 | L15: =+F15-J15 -> 9000000
B18: RUPEES: 2023 | D18: =SUM(D11:D17) -> 138000000 | E18: =SUM(E11:E15) -> 0 | F18: =SUM(F11:F15) -> 138000000 | H18: =SUM(H11:H15) -> 0 | I18: =SUM(I11:I15) -> 0 | J18: =SUM(J11:J15) -> 0 | L18: =SUM(L11:L15) -> 138000000
B20: RUPEES : 2022 | D20: =D18 -> 138000000 | E20: 0 | F20: =F18 -> 138000000 | L20: =L18 -> 138000000

Sheet Sheet3
F4: 2019
B5: Name of related parties | D5: Nature of transactions | F5: Rupees
B7: HM Holding Company | D7: Working capital assistance provided | F7: ='Trial Combine 19'!J242 -> 25401670

Sheet FIXED ASSETS
E4: COST | P4: DEPRECIATION | Z4: Written down | AB4: DEPRECIATION | AD4: Written down
B5: Particulars | E5: As at | G5: Additions | I5: Deletion / | L5: As at | N5: Rate | P5: As at | R5: Deletion / Transfer | T5: Adjustment | V5: For the | X5: As at | Z5: value as on | AB5: For the | AD5: value as on
E6: July 01, 2018 | I6: Transfer | L6: June 30, 2019 | N6: % | P6: July 01, 2018 | V6: year | X6: June 30, 2019 | Z6: June 30, 2019 | AB6: year | AD6: June 30, 2020 | AF6: =K24-SOFP!#REF! -> #REF!
B9: Owned
B11: Furniture and fixtures | E11: 0 | G11: 0 | I11: 0 | K11: 700000 | L11: =E11+K11 -> 700000 | N11: 30 | P11: 0 | R11: 0 | T11: 0 | V11: 35000 | X11: 35000 | Z11: =L11-X11 -> 665000 | AB11: =Z11*N11% -> 199500 | AD11: =Z11-AB11 -> 465500 | AF11: 276203 | AG11: =X11-AF11 -> -241203 | AH11: =E11-P11 -> 0 | AI11: =AH11*0.1 -> 0
B12: Office equipment | E12: 0 | G12: 0 | I12: 0 | K12: 112428 | L12: =E12+K12 -> 112428 | N12: 15 | P12: 0 | R12: 0 | T12: 0 | V12: 4479 | X12: 4479 | Z12: =L12-X12 -> 107949 | AB12: =Z12*N12% -> 16192.35 | AD12: =Z12-AB12 -> 91756.65 | AF12: 246294 | AG12: =X12-AF12 -> -241815 | AH12: =E12-P12 -> 0 | AI12: =AH12*0.1 -> 0 | AJ12: =G12*0.1 -> 0
B13: Computers | E13: 0 | K13: =94175+84293+180890 -> 359358 | L13: =E13+K13 -> 359358 | N13: 15 | P13: 0 | V13: 61441 | X13: 61441 | Z13: =L13-X13 -> 297917 | AB13: =Z13*N13% -> 44687.55 | AD13: =Z13-AB13 -> 253229.45
B14: Machinery | E14: 0 | K14: =282722+487639+130000+1670980+160000+45000+114618 -> 2890959 | L14: =E14+K14 -> 2890959 | N14: 15 | P14: 0 | V14: 163328 | X14: 163328 | Z14: =L14-X14 -> 2727631 | AB14: =Z14*N14% -> 409144.65 | AD14: =Z14-AB14 -> 2318486.4
